<?xml version="1.0" encoding="utf-8"?>
<!-- =================================================================================== -->
<!-- |    This document was autogenerated by xacro from mobileman_rviz.xacro           | -->
<!-- |    EDITING THIS FILE BY HAND IS NOT RECOMMENDED                                 | -->
<!-- =================================================================================== -->
<robot name="prototype2">
  <link name="base_link">
    <!-- <inertial>
      <origin
        xyz="-0.22833 -0.0010016 0.042759"
        rpy="0 0 0" />
      <mass
        value="180" />
      <inertia
        ixx="0.65386"
        ixy="4.200"
        ixz="2.0031"
        iyy="1.3175"
        iyz="1.5"
        izz="1.4532" />
    </inertial> -->
    <visual>
      <origin rpy="0 0 0" xyz="0 0 0"/>
      <geometry>
        <mesh filename="package://mobileman_simulation/meshes/base_link.STL"/>
      </geometry>
      <material name="">
        <color rgba="0.75294 0.75294 0.75294 1"/>
      </material>
    </visual>
    <collision>
      <origin rpy="0 0 0" xyz="0 0 0"/>
      <geometry>
        <box size="0.370 0.832 0.320"/>
      </geometry>
    </collision>
  </link>
  <link name="front_left_link">
    <inertial>
      <mass value="0.2"/>
      <origin rpy="1.57 0 0" xyz="0 0 0"/>
      <inertia ixx="0.01" ixy="0" ixz="0" iyy="0.1" iyz="0" izz="0.01"/>
    </inertial>
    <!-- <visual name="$(name)_visual"> -->
    <visual>
      <origin rpy="1.57 0 0" xyz="0 0 0"/>
      <geometry>
        <cylinder length="0.001" radius="0.2155"/>
      </geometry>
    </visual>
    <!-- <collision name="$(name)_collision"> -->
    <collision>
      <origin rpy="1.57 0 0" xyz="0 0 0"/>
      <geometry>
        <cylinder length="0.085" radius="0.2255"/>
      </geometry>
    </collision>
  </link>
  <joint name="front_left_joint" type="continuous">
    <origin rpy="0 0 0" xyz="0.252 0.257 -0.05"/>
    <child link="front_left_link"/>
    <parent link="base_link"/>
    <axis rpy="0 0 0" xyz="0 1 0"/>
    <limit effort="10000" velocity="1000"/>
    <joint_properties damping="1.0" friction="1.0"/>
  </joint>
  <link name="front_right_link">
    <inertial>
      <mass value="0.2"/>
      <origin rpy="1.57 0 0" xyz="0 0 0"/>
      <inertia ixx="0.01" ixy="0" ixz="0" iyy="0.1" iyz="0" izz="0.01"/>
    </inertial>
    <!-- <visual name="$(name)_visual"> -->
    <visual>
      <origin rpy="1.57 0 0" xyz="0 0 0"/>
      <geometry>
        <cylinder length="0.001" radius="0.2155"/>
      </geometry>
    </visual>
    <!-- <collision name="$(name)_collision"> -->
    <collision>
      <origin rpy="1.57 0 0" xyz="0 0 0"/>
      <geometry>
        <cylinder length="0.085" radius="0.2255"/>
      </geometry>
    </collision>
  </link>
  <joint name="front_right_joint" type="continuous">
    <origin rpy="0 0 0" xyz="-0.252 0.257 -0.05"/>
    <child link="front_right_link"/>
    <parent link="base_link"/>
    <axis rpy="0 0 0" xyz="0 1 0"/>
    <limit effort="10000" velocity="1000"/>
    <joint_properties damping="1.0" friction="1.0"/>
  </joint>
  <link name="rear_left_link">
    <inertial>
      <mass value="0.2"/>
      <origin rpy="1.57 0 0" xyz="0 0 0"/>
      <inertia ixx="0.01" ixy="0" ixz="0" iyy="0.1" iyz="0" izz="0.01"/>
    </inertial>
    <!-- <visual name="$(name)_visual"> -->
    <visual>
      <origin rpy="1.57 0 0" xyz="0 0 0"/>
      <geometry>
        <cylinder length="0.001" radius="0.2155"/>
      </geometry>
    </visual>
    <!-- <collision name="$(name)_collision"> -->
    <collision>
      <origin rpy="1.57 0 0" xyz="0 0 0"/>
      <geometry>
        <cylinder length="0.085" radius="0.2255"/>
      </geometry>
    </collision>
  </link>
  <joint name="rear_left_joint" type="continuous">
    <origin rpy="0 0 0" xyz="0.252 -0.295 -0.12"/>
    <child link="rear_left_link"/>
    <parent link="base_link"/>
    <axis rpy="0 0 0" xyz="0 1 0"/>
    <limit effort="10000" velocity="1000"/>
    <joint_properties damping="1.0" friction="1.0"/>
  </joint>
  <link name="rear_right_link">
    <inertial>
      <mass value="0.2"/>
      <origin rpy="1.57 0 0" xyz="0 0 0"/>
      <inertia ixx="0.01" ixy="0" ixz="0" iyy="0.1" iyz="0" izz="0.01"/>
    </inertial>
    <!-- <visual name="$(name)_visual"> -->
    <visual>
      <origin rpy="1.57 0 0" xyz="0 0 0"/>
      <geometry>
        <cylinder length="0.001" radius="0.2155"/>
      </geometry>
    </visual>
    <!-- <collision name="$(name)_collision"> -->
    <collision>
      <origin rpy="1.57 0 0" xyz="0 0 0"/>
      <geometry>
        <cylinder length="0.085" radius="0.2255"/>
      </geometry>
    </collision>
  </link>
  <joint name="rear_right_joint" type="continuous">
    <origin rpy="0 0 0" xyz="-0.252 -0.295 -0.12"/>
    <child link="rear_right_link"/>
    <parent link="base_link"/>
    <axis rpy="0 0 0" xyz="0 1 0"/>
    <limit effort="10000" velocity="1000"/>
    <joint_properties damping="1.0" friction="1.0"/>
  </joint>
  <link name="Link1">
    <inertial>
      <origin rpy="0 0 0" xyz="0.30661 0.13018 0"/>
      <mass value="10.512"/>
      <inertia ixx="0.12168" ixy="-6.1853E-17" ixz="-1.0133E-15" iyy="0.36652" iyz="3.4411E-17" izz="0.25354"/>
    </inertial>
    <visual>
      <origin rpy="0 0 0" xyz="0 0 0"/>
      <geometry>
        <mesh filename="package://mobileman_simulation/meshes/Link1.STL"/>
      </geometry>
      <material name="">
        <color rgba="0.5 0.5 0.5 1"/>
      </material>
    </visual>
    <collision>
      <origin rpy="0 0 0" xyz="0 0 0"/>
      <geometry>
        <mesh filename="package://mobileman_simulation/meshes/Link1.STL"/>
      </geometry>
    </collision>
  </link>
  <joint name="fork_rotational_joint" type="revolute">
    <origin rpy="1.5708 0 -3.1416" xyz="0.0975 0 0.409"/>
    <parent link="base_link"/>
    <child link="Link1"/>
    <axis xyz="0 0 1"/>
    <limit effort="1000" lower="0" upper="1.57" velocity="0"/>
    <dynamics damping="10" friction="10"/>
  </joint>
  <link name="Link2">
    <inertial>
      <origin rpy="0 0 0" xyz="0 0.13165 -0.3945"/>
      <mass value="7.4392"/>
      <inertia ixx="0.26451" ixy="-4.5117E-15" ixz="-1.2876E-14" iyy="0.22881" iyz="-0.059461" izz="0.10508"/>
    </inertial>
    <visual>
      <origin rpy="0 0 0" xyz="0 0 0"/>
      <geometry>
        <mesh filename="package://mobileman_simulation/meshes/Link2.STL"/>
      </geometry>
      <material name="">
        <color rgba="0.75294 0.75294 0.75294 1"/>
      </material>
    </visual>
    <collision>
      <origin rpy="0 0 0" xyz="0 0 0"/>
      <geometry>
        <mesh filename="package://mobileman_simulation/meshes/Link2.STL"/>
      </geometry>
    </collision>
  </link>
  <joint name="fork_linear_joint" type="prismatic">
    <origin rpy="0 -1.5708 0" xyz="-0.12 0.158 0"/>
    <parent link="Link1"/>
    <child link="Link2"/>
    <!-- <axis xyz="-1 0 0" /> -->
    <axis xyz="0 0 1"/>
    <limit effort="1000" lower="0" upper="0.5" velocity="0"/>
  </joint>
  <!--IMU-->
  <!--Laser Scanner-->
</robot>
